Workbook

Sheet исходные
A1: № | B1: 916.1 | C1: 916.2 | D1: 916.3 | E1: 916.4 | F1: 911.1 | G1: 911.2 | H1: 911.3 | I1: 911.4 | J1: 911.5 | K1: 915.01 | L1: 915.02 | M1: 915.03 | N1: 915.04 | O1: 915.05 | P1: 913.1 | Q1: 913.2 | R1: 913.3 | S1: 913.4 | T1: 913.5
A2: Брусника | B2: 4.4 | C2: 0.7 | D2: 1.75 | E2: 0 | F2: 0 | G2: 0 | H2: 0 | I2: 0 | J2: 0 | K2: 0 | L2: 0 | M2: 0 | N2: 0 | O2: 0 | P2: 0 | Q2: 0 | R2: 0.2 | S2: 0 | T2: 1
A3: Вейник | B3: 7.5 | C3: 37.5 | D3: 5.2 | E3: 19.3 | F3: 6.2 | G3: 5.8 | H3: 18.2 | I3: 4.4 | J3: 5.1 | K3: 23.6 | L3: 19.5 | M3: 23.2 | N3: 6.1 | O3: 17 | P3: 5.1 | Q3: 6.6 | R3: 12.8 | S3: 4.6 | T3: 6
A4: Вероника дубравная | B4: 0 | C4: 0 | D4: 0 | E4: 0 | F4: 0 | G4: 0.05 | H4: 0.02 | I4: 0.01 | J4: 0 | K4: 0 | L4: 0.2 | M4: 0 | N4: 0 | O4: 0 | P4: 0 | Q4: 0 | R4: 0 | S4: 0 | T4: 0
A5: Герань | B5: 0.03 | C5: 0.2 | D5: 0 | E5: 0.1 | F5: 1.6 | G5: 0.7 | H5: 0.1 | I5: 0.03 | J5: 1.5 | K5: 0 | L5: 0 | M5: 0.05 | N5: 0.2 | O5: 0 | P5: 0.9 | Q5: 0 | R5: 0.01 | S5: 0.3 | T5: 0.02
A6: Горошик лесной | B6: 0 | C6: 0 | D6: 0 | E6: 0 | F6: 0.01 | G6: 0 | H6: 0 | I6: 0.05 | J6: 0 | K6: 0 | L6: 0 | M6: 0.1 | N6: 0.1 | O6: 0.3 | P6: 0.2 | Q6: 0.1 | R6: 0 | S6: 0.4 | T6: 0.1
A7: Грушанка | B7: 0 | C7: 0 | D7: 0.1 | E7: 0 | F7: 0 | G7: 0 | H7: 0.02 | I7: 0 | J7: 0 | K7: 0 | L7: 0 | M7: 0 | N7: 0 | O7: 0 | P7: 2.3 | Q7: 3.3 | R7: 0.5 | S7: 0 | T7: 0
A8: Звездчатка жестколистная | B8: 0 | C8: 0 | D8: 0 | E8: 0 | F8: 0 | G8: 0.5 | H8: 0.35 | I8: 0.1 | J8: 0.3 | K8: 0.8 | L8: 1.5 | M8: 0.7 | N8: 0.7 | O8: 0.7 | P8: 0 | Q8: 0 | R8: 0.05 | S8: 0.6 | T8: 1.5
A9: Земляника | B9: 0 | C9: 0 | D9: 0 | E9: 0 | F9: 0 | G9: 0 | H9: 0 | I9: 0 | J9: 1.6 | K9: 0 | L9: 2.4 | M9: 0 | N9: 0 | O9: 0.2 | P9: 0.2 | Q9: 0 | R9: 0 | S9: 0 | T9: 0
A10: Золотарник | B10: 0.25 | C10: 0.2 | D10: 1.9 | E10: 0.05 | F10: 0 | G10: 0.8 | H10: 0 | I10: 0 | J10: 1.7 | K10: 0 | L10: 1.9 | M10: 0.25 | N10: 0 | O10: 0.1 | P10: 0 | Q10: 0 | R10: 0.3 | S10: 0.05 | T10: 0
A11: Иван-чай | B11: 0.5 | C11: 1.5 | D11: 3.2 | E11: 0.3 | F11: 0 | G11: 0 | H11: 0.4 | I11: 0 | J11: 0 | K11: 0 | L11: 0 | M11: 0 | N11: 0 | O11: 0 | P11: 0 | Q11: 0 | R11: 0 | S11: 0 | T11: 0
A12: Кислица | B12: 0 | C12: 0 | D12: 0 | E12: 0 | F12: 2.1 | G12: 0.8 | H12: 0.4 | I12: 0.5 | J12: 0.5 | K12: 0.4 | L12: 0.2 | M12: 0.9 | N12: 0.8 | O12: 0.45 | P12: 0.05 | Q12: 0.1 | R12: 0.5 | S12: 0.85 | T12: 0.1
A13: Коротконожка | B13: 0 | C13: 0 | D13: 0 | E13: 0 | F13: 2.8 | G13: 2.4 | H13: 0 | I13: 3.3 | J13: 0 | K13: 4.7 | L13: 0 | M13: 0 | N13: 0 | O13: 0.8 | P13: 0 | Q13: 0 | R13: 0.05 | S13: 0.1 | T13: 0
... A23: Седмичник | B23: 0 | C23: 0.4 | D23: 0.2 | E23: 0.6 | F23: 0 | G23: 0.1 | H23: 0.2 | I23: 0.1 | J23: 0.03 | K23: 0 | L23: 0 | M23: 0 | N23: 0 | O23: 0 | P23: 0 | Q23: 0 | R23: 0 | S23: 0 | T23: 0.3
A24: Сныть | B24: 0 | C24: 0 | D24: 0 | E24: 0 | F24: 4.2 | G24: 5.2 | I24: 6.3 | J24: 0.9 | K24: 0 | L24: 0 | M24: 0 | N24: 0 | O24: 0 | P24: 0 | Q24: 0 | R24: 0.3 | S24: 0 | T24: 0
A25: Фиалка собачья | B25: 0.05 | C25: 0.5 | D25: 0.5 | E25: 0.1 | F25: 0.05 | G25: 0.1 | H25: 0 | I25: 0 | J25: 0.2 | K25: 0 | L25: 0 | M25: 0 | N25: 0 | O25: 0 | P25: 0 | Q25: 0 | R25: 0 | S25: 0 | T25: 0
A26: Черника | B26: 2.5 | C26: 1.2 | D26: 1.2 | E26: 1.4 | F26: 6 | G26: 5.9 | H26: 1.1 | I26: 0.45 | J26: 4.5 | K26: 2.8 | L26: 0 | M26: 0 | N26: 11.6 | O26: 5.7 | P26: 19 | Q26: 27.5 | R26: 38.6 | S26: 9.85 | T26: 7.1
A27: Чина весенняя | B27: 0 | C27: 0 | D27: 0 | E27: 0 | F27: 0.5 | G27: 0.65 | H27: 1.3 | I27: 0 | J27: 0.5 | K27: 0 | L27: 0.3 | M27: 3.9 | N27: 2.5 | O27: 0.8 | P27: 0 | Q27: 0 | R27: 0.8 | S27: 0.4 | T27: 1.1
A28: Чина луговая | B28: 0 | C28: 0 | D28: 0 | E28: 0 | F28: 0 | G28: 0.05 | H28: 0.1 | I28: 0 | J28: 0 | K28: 0 | L28: 0 | M28: 0 | N28: 0 | O28: 0 | P28: 0 | Q28: 0 | R28: 0 | S28: 0 | T28: 0
A29: Щучка | B29: 0 | C29: 0 | D29: 0 | E29: 0 | F29: 0.02 | G29: 0.05 | H29: 0 | I29: 0.4 | J29: 0 | K29: 0 | L29: 0 | M29: 0 | N29: 0 | O29: 0 | P29: 0 | Q29: 0 | R29: 0 | S29: 0 | T29: 0
A30: Ястребинка | B30: 0 | C30: 0.3 | D30: 0 | E30: 0.7 | F30: 0 | G30: 0 | H30: 0 | I30: 0 | J30: 0 | K30: 0 | L30: 0 | M30: 0 | N30: 0 | O30: 0 | P30: 0 | Q30: 0 | R30: 0 | S30: 0 | T30: 0
A31: Ястребиночка | B31: 0 | C31: 0 | D31: 0 | E31: 0 | F31: 0.2 | G31: 0.5 | H31: 0.1 | I31: 0 | J31: 0 | K31: 0 | L31: 0 | M31: 0 | N31: 0 | O31: 0 | P31: 0 | Q31: 0 | R31: 0 | S31: 0 | T31: 0
A32: Чина гороховидная | B32: 0 | C32: 0 | D32: 0 | E32: 0 | F32: 0 | G32: 0 | H32: 0 | I32: 0 | J32: 0 | K32: 0 | L32: 0 | M32: 0 | N32: 0 | O32: 0 | P32: 0.2 | Q32: 0 | R32: 0 | S32: 0 | T32: 0
A33: Линнея северная | B33: 0 | C33: 0 | D33: 0 | E33: 0 | F33: 0 | G33: 0 | H33: 0 | I33: 0 | J33: 0 | K33: 0 | L33: 0 | M33: 0 | N33: 0 | O33: 0 | P33: 0.6 | Q33: 0 | R33: 0 | S33: 0 | T33: 0
A34: Клевер люпиновидный | B34: 0 | C34: 0 | D34: 0 | E34: 0 | F34: 0 | G34: 0 | H34: 0 | I34: 0 | J34: 0 | K34: 0 | L34: 0 | M34: 0 | N34: 0 | O34: 0 | P34: 0 | Q34: 0 | R34: 0 | S34: 3.55 | T34: 0

Sheet накопительные
A1: № | B1: 1 | C1: 2 | D1: 3 | E1: 4 | F1: 5 | G1: 6 | H1: 7 | I1: 8 | J1: 9 | K1: 10 | L1: 11 | M1: 12 | N1: 13 | O1: 14 | P1: 15 | Q1: 16 | R1: 17 | S1: 18 | T1: 19
A2: Брусника | B2: =исходные!B2 -> 4.4 | C2: =B2+исходные!C2 -> 5.1 | D2: =C2+исходные!D2 -> 6.85 | E2: =D2+исходные!E2 -> 6.85 | F2: =E2+исходные!F2 -> 6.85 | G2: =F2+исходные!G2 -> 6.85 | H2: =G2+исходные!H2 -> 6.85 | I2: =H2+исходные!I2 -> 6.85 | J2: =I2+исходные!J2 -> 6.85 | ... T2: =S2+исходные!T2 -> 8.05
A3: Вейник | B3: =исходные!B3 -> 7.5 | C3: =B3+исходные!C3 -> 45 | D3: =C3+исходные!D3 -> 50.2 | E3: =D3+исходные!E3 -> 69.5 | F3: =E3+исходные!F3 -> 75.7 | G3: =F3+исходные!G3 -> 81.5 | H3: =G3+исходные!H3 -> 99.7 | I3: =H3+исходные!I3 -> 104.1 | J3: =I3+исходные!J3 -> 109.2 | ... T3: =S3+исходные!T3 -> 233.7
A4: Вероника дубравная | B4: =исходные!B4 -> 0 | C4: =B4+исходные!C4 -> 0 | D4: =C4+исходные!D4 -> 0 | E4: =D4+исходные!E4 -> 0 | F4: =E4+исходные!F4 -> 0 | G4: =F4+исходные!G4 -> 0.05 | H4: =G4+исходные!H4 -> 0.07 | I4: =H4+исходные!I4 -> 0.08 | J4: =I4+исходные!J4 -> 0.08 | ... T4: =S4+исходные!T4 -> 0.28
A5: Герань | B5: =исходные!B5 -> 0.03 | C5: =B5+исходные!C5 -> 0.23 | D5: =C5+исходные!D5 -> 0.23 | E5: =D5+исходные!E5 -> 0.33 | F5: =E5+исходные!F5 -> 1.93 | G5: =F5+исходные!G5 -> 2.63 | H5: =G5+исходные!H5 -> 2.73 | I5: =H5+исходные!I5 -> 2.76 | J5: =I5+исходные!J5 -> 4.26 | ... T5: =S5+исходные!T5 -> 5.74
A6: Горошик лесной | B6: =исходные!B6 -> 0 | C6: =B6+исходные!C6 -> 0 | D6: =C6+исходные!D6 -> 0 | E6: =D6+исходные!E6 -> 0 | F6: =E6+исходные!F6 -> 0.01 | G6: =F6+исходные!G6 -> 0.01 | H6: =G6+исходные!H6 -> 0.01 | I6: =H6+исходные!I6 -> 0.06 | J6: =I6+исходные!J6 -> 0.06 | ... T6: =S6+исходные!T6 -> 1.36
A7: Грушанка | B7: =исходные!B7 -> 0 | C7: =B7+исходные!C7 -> 0 | D7: =C7+исходные!D7 -> 0.1 | E7: =D7+исходные!E7 -> 0.1 | F7: =E7+исходные!F7 -> 0.1 | G7: =F7+исходные!G7 -> 0.1 | H7: =G7+исходные!H7 -> 0.12 | I7: =H7+исходные!I7 -> 0.12 | J7: =I7+исходные!J7 -> 0.12 | ... T7: =S7+исходные!T7 -> 6.22
A8: Звездчатка жестколистная | B8: =исходные!B8 -> 0 | C8: =B8+исходные!C8 -> 0 | D8: =C8+исходные!D8 -> 0 | E8: =D8+исходные!E8 -> 0 | F8: =E8+исходные!F8 -> 0 | G8: =F8+исходные!G8 -> 0.5 | H8: =G8+исходные!H8 -> 0.85 | I8: =H8+исходные!I8 -> 0.95 | J8: =I8+исходные!J8 -> 1.25 | ... T8: =S8+исходные!T8 -> 7.8
A9: Земляника | B9: =исходные!B9 -> 0 | C9: =B9+исходные!C9 -> 0 | D9: =C9+исходные!D9 -> 0 | E9: =D9+исходные!E9 -> 0 | F9: =E9+исходные!F9 -> 0 | G9: =F9+исходные!G9 -> 0 | H9: =G9+исходные!H9 -> 0 | I9: =H9+исходные!I9 -> 0 | J9: =I9+исходные!J9 -> 1.6 | ... T9: =S9+исходные!T9 -> 4.4
A10: Золотарник | B10: =исходные!B10 -> 0.25 | C10: =B10+исходные!C10 -> 0.45 | D10: =C10+исходные!D10 -> 2.35 | E10: =D10+исходные!E10 -> 2.4 | F10: =E10+исходные!F10 -> 2.4 | G10: =F10+исходные!G10 -> 3.2 | H10: =G10+исходные!H10 -> 3.2 | I10: =H10+исходные!I10 -> 3.2 | J10: =I10+исходные!J10 -> 4.9 | ... T10: =S10+исходные!T10 -> 7.5
A11: Иван-чай | B11: =исходные!B11 -> 0.5 | C11: =B11+исходные!C11 -> 2 | D11: =C11+исходные!D11 -> 5.2 | E11: =D11+исходные!E11 -> 5.5 | F11: =E11+исходные!F11 -> 5.5 | G11: =F11+исходные!G11 -> 5.5 | H11: =G11+исходные!H11 -> 5.9 | I11: =H11+исходные!I11 -> 5.9 | J11: =I11+исходные!J11 -> 5.9 | ... T11: =S11+исходные!T11 -> 5.9
A12: Кислица | B12: =исходные!B12 -> 0 | C12: =B12+исходные!C12 -> 0 | D12: =C12+исходные!D12 -> 0 | E12: =D12+исходные!E12 -> 0 | F12: =E12+исходные!F12 -> 2.1 | G12: =F12+исходные!G12 -> 2.9 | H12: =G12+исходные!H12 -> 3.3 | I12: =H12+исходные!I12 -> 3.8 | J12: =I12+исходные!J12 -> 4.3 | ... T12: =S12+исходные!T12 -> 8.65
A13: Коротконожка | B13: =исходные!B13 -> 0 | C13: =B13+исходные!C13 -> 0 | D13: =C13+исходные!D13 -> 0 | E13: =D13+исходные!E13 -> 0 | F13: =E13+исходные!F13 -> 2.8 | G13: =F13+исходные!G13 -> 5.2 | H13: =G13+исходные!H13 -> 5.2 | I13: =H13+исходные!I13 -> 8.5 | J13: =I13+исходные!J13 -> 8.5 | ... T13: =S13+исходные!T13 -> 14.15
... A34: Клевер люпиновидный | B34: =исходные!B34 -> 0 | C34: =B34+исходные!C34 -> 0 | D34: =C34+исходные!D34 -> 0 | E34: =D34+исходные!E34 -> 0 | F34: =E34+исходные!F34 -> 0 | G34: =F34+исходные!G34 -> 0 | H34: =G34+исходные!H34 -> 0 | I34: =H34+исходные!I34 -> 0 | J34: =I34+исходные!J34 -> 0 | ... T34: =S34+исходные!T34 -> 3.55
A37: S | B37: =COUNTIF(B2:B34,">0") -> 13 | C37: =COUNTIF(C2:C34,">0") -> 15 | D37: =COUNTIF(D2:D34,">0") -> 17 | E37: =COUNTIF(E2:E34,">0") -> 17 | F37: =COUNTIF(F2:F34,">0") -> 26 | G37: =COUNTIF(G2:G34,">0") -> 29 | H37: =COUNTIF(H2:H34,">0") -> 29 | I37: =COUNTIF(I2:I34,">0") -> 29 | ... T37: =COUNTIF(T2:T34,">0") -> 33
A38: N | B38: =SUM(B2:B34) -> 17.76 | C38: =SUM(C2:C34) -> 71.36 | D38: =SUM(D2:D34) -> 95.36 | E38: =SUM(E2:E34) -> 127.56 | F38: =SUM(F2:F34) -> 160.34 | G38: =SUM(G2:G34) -> 190.49 | H38: =SUM(H2:H34) -> 216.38 | I38: =SUM(I2:I34) -> 234.95 | ... T38: =SUM(T2:T34) -> 659.57

Sheet q = 1
A1: № | B1: 1 | C1: 2 | D1: 3 | E1: 4 | F1: 5 | G1: 6 | H1: 7 | I1: 8 | J1: 9 | K1: 10 | L1: 11 | M1: 12 | N1: 13 | O1: 14 | P1: 15 | Q1: 16 | R1: 17 | S1: 18 | T1: 19
A2: Брусника | B2: =(накопительные!B2/SUM(накопительные!B$2:B$34))^$B$39 -> 0.24774775 | C2: =(накопительные!C2/SUM(накопительные!C$2:C$34))^$B$39 -> 0.07146861 | D2: =(накопительные!D2/SUM(накопительные!D$2:D$34))^$B$39 -> 0.071833054 | E2: =(накопительные!E2/SUM(накопительные!E$2:E$34))^$B$39 -> 0.05370022 | F2: =(накопительные!F2/SUM(накопительные!F$2:F$34))^$B$39 -> 0.042721716 | G2: =(накопительные!G2/SUM(накопительные!G$2:G$34))^$B$39 -> 0.035959893 | H2: =(накопительные!H2/SUM(накопительные!H$2:H$34))^$B$39 -> 0.03165727 | I2: =(накопительные!I2/SUM(накопительные!I$2:I$34))^$B$39 -> 0.029155139 | ... T2: =(накопительные!T2/SUM(накопительные!T$2:T$34))^$B$39 -> 0.012204921
A3: Вейник | B3: =(накопительные!B3/SUM(накопительные!B$2:B$34))^$B$39 -> 0.4222973 | C3: =(накопительные!C3/SUM(накопительные!C$2:C$34))^$B$39 -> 0.63060538 | D3: =(накопительные!D3/SUM(накопительные!D$2:D$34))^$B$39 -> 0.52642617 | E3: =(накопительные!E3/SUM(накопительные!E$2:E$34))^$B$39 -> 0.54484164 | F3: =(накопительные!F3/SUM(накопительные!F$2:F$34))^$B$39 -> 0.47212174 | G3: =(накопительные!G3/SUM(накопительные!G$2:G$34))^$B$39 -> 0.42784398 | H3: =(накопительные!H3/SUM(накопительные!H$2:H$34))^$B$39 -> 0.46076347 | I3: =(накопительные!I3/SUM(накопительные!I$2:I$34))^$B$39 -> 0.44307299 | ... T3: =(накопительные!T3/SUM(накопительные!T$2:T$34))^$B$39 -> 0.35432176
A4: Вероника дубравная | B4: =(накопительные!B4/SUM(накопительные!B$2:B$34))^$B$39 -> 0 | C4: =(накопительные!C4/SUM(накопительные!C$2:C$34))^$B$39 -> 0 | D4: =(накопительные!D4/SUM(накопительные!D$2:D$34))^$B$39 -> 0 | E4: =(накопительные!E4/SUM(накопительные!E$2:E$34))^$B$39 -> 0 | F4: =(накопительные!F4/SUM(накопительные!F$2:F$34))^$B$39 -> 0 | G4: =(накопительные!G4/SUM(накопительные!G$2:G$34))^$B$39 -> 0.00026248097 | H4: =(накопительные!H4/SUM(накопительные!H$2:H$34))^$B$39 -> 0.00032350495 | I4: =(накопительные!I4/SUM(накопительные!I$2:I$34))^$B$39 -> 0.00034049798 | ... T4: =(накопительные!T4/SUM(накопительные!T$2:T$34))^$B$39 -> 0.000424519
A5: Герань | B5: =(накопительные!B5/SUM(накопительные!B$2:B$34))^$B$39 -> 0.0016891892 | C5: =(накопительные!C5/SUM(накопительные!C$2:C$34))^$B$39 -> 0.0032230942 | D5: =(накопительные!D5/SUM(накопительные!D$2:D$34))^$B$39 -> 0.0024119128 | E5: =(накопительные!E5/SUM(накопительные!E$2:E$34))^$B$39 -> 0.0025870179 | F5: =(накопительные!F5/SUM(накопительные!F$2:F$34))^$B$39 -> 0.012036922 | G5: =(накопительные!G5/SUM(накопительные!G$2:G$34))^$B$39 -> 0.013806499 | H5: =(накопительные!H5/SUM(накопительные!H$2:H$34))^$B$39 -> 0.012616693 | I5: =(накопительные!I5/SUM(накопительные!I$2:I$34))^$B$39 -> 0.01174718 | ... T5: =(накопительные!T5/SUM(накопительные!T$2:T$34))^$B$39 -> 0.0087026396
A6: Горошик лесной | B6: =(накопительные!B6/SUM(накопительные!B$2:B$34))^$B$39 -> 0 | C6: =(накопительные!C6/SUM(накопительные!C$2:C$34))^$B$39 -> 0 | D6: =(накопительные!D6/SUM(накопительные!D$2:D$34))^$B$39 -> 0 | E6: =(накопительные!E6/SUM(накопительные!E$2:E$34))^$B$39 -> 0 | F6: =(накопительные!F6/SUM(накопительные!F$2:F$34))^$B$39 -> 6.2367469e-05 | G6: =(накопительные!G6/SUM(накопительные!G$2:G$34))^$B$39 -> 5.2496194e-05 | H6: =(накопительные!H6/SUM(накопительные!H$2:H$34))^$B$39 -> 4.6214992e-05 | I6: =(накопительные!I6/SUM(накопительные!I$2:I$34))^$B$39 -> 0.00025537348 | ... T6: =(накопительные!T6/SUM(накопительные!T$2:T$34))^$B$39 -> 0.0020619495
A7: Грушанка | B7: =(накопительные!B7/SUM(накопительные!B$2:B$34))^$B$39 -> 0 | C7: =(накопительные!C7/SUM(накопительные!C$2:C$34))^$B$39 -> 0 | D7: =(накопительные!D7/SUM(накопительные!D$2:D$34))^$B$39 -> 0.0010486577 | E7: =(накопительные!E7/SUM(накопительные!E$2:E$34))^$B$39 -> 0.00078394481 | F7: =(накопительные!F7/SUM(накопительные!F$2:F$34))^$B$39 -> 0.00062367469 | G7: =(накопительные!G7/SUM(накопительные!G$2:G$34))^$B$39 -> 0.00052496194 | H7: =(накопительные!H7/SUM(накопительные!H$2:H$34))^$B$39 -> 0.00055457991 | I7: =(накопительные!I7/SUM(накопительные!I$2:I$34))^$B$39 -> 0.00051074697 | ... T7: =(накопительные!T7/SUM(накопительные!T$2:T$34))^$B$39 -> 0.0094303865
A8: Звездчатка жестколистная | B8: =(накопительные!B8/SUM(накопительные!B$2:B$34))^$B$39 -> 0 | C8: =(накопительные!C8/SUM(накопительные!C$2:C$34))^$B$39 -> 0 | D8: =(накопительные!D8/SUM(накопительные!D$2:D$34))^$B$39 -> 0 | E8: =(накопительные!E8/SUM(накопительные!E$2:E$34))^$B$39 -> 0 | F8: =(накопительные!F8/SUM(накопительные!F$2:F$34))^$B$39 -> 0 | G8: =(накопительные!G8/SUM(накопительные!G$2:G$34))^$B$39 -> 0.0026248097 | H8: =(накопительные!H8/SUM(накопительные!H$2:H$34))^$B$39 -> 0.0039282743 | I8: =(накопительные!I8/SUM(накопительные!I$2:I$34))^$B$39 -> 0.0040434135 | ... T8: =(накопительные!T8/SUM(накопительные!T$2:T$34))^$B$39 -> 0.011825887
A9: Земляника | B9: =(накопительные!B9/SUM(накопительные!B$2:B$34))^$B$39 -> 0 | C9: =(накопительные!C9/SUM(накопительные!C$2:C$34))^$B$39 -> 0 | D9: =(накопительные!D9/SUM(накопительные!D$2:D$34))^$B$39 -> 0 | E9: =(накопительные!E9/SUM(накопительные!E$2:E$34))^$B$39 -> 0 | F9: =(накопительные!F9/SUM(накопительные!F$2:F$34))^$B$39 -> 0 | G9: =(накопительные!G9/SUM(накопительные!G$2:G$34))^$B$39 -> 0 | H9: =(накопительные!H9/SUM(накопительные!H$2:H$34))^$B$39 -> 0 | I9: =(накопительные!I9/SUM(накопительные!I$2:I$34))^$B$39 -> 0 | ... T9: =(накопительные!T9/SUM(накопительные!T$2:T$34))^$B$39 -> 0.0066710129
A10: Золотарник | B10: =(накопительные!B10/SUM(накопительные!B$2:B$34))^$B$39 -> 0.014076577 | C10: =(накопительные!C10/SUM(накопительные!C$2:C$34))^$B$39 -> 0.0063060538 | D10: =(накопительные!D10/SUM(накопительные!D$2:D$34))^$B$39 -> 0.024643456 | E10: =(накопительные!E10/SUM(накопительные!E$2:E$34))^$B$39 -> 0.018814675 | F10: =(накопительные!F10/SUM(накопительные!F$2:F$34))^$B$39 -> 0.014968193 | G10: =(накопительные!G10/SUM(накопительные!G$2:G$34))^$B$39 -> 0.016798782 | H10: =(накопительные!H10/SUM(накопительные!H$2:H$34))^$B$39 -> 0.014788797 | I10: =(накопительные!I10/SUM(накопительные!I$2:I$34))^$B$39 -> 0.013619919 | ... T10: =(накопительные!T10/SUM(накопительные!T$2:T$34))^$B$39 -> 0.011371045
A11: Иван-чай | B11: =(накопительные!B11/SUM(накопительные!B$2:B$34))^$B$39 -> 0.028153153 | C11: =(накопительные!C11/SUM(накопительные!C$2:C$34))^$B$39 -> 0.028026906 | D11: =(накопительные!D11/SUM(накопительные!D$2:D$34))^$B$39 -> 0.054530201 | E11: =(накопительные!E11/SUM(накопительные!E$2:E$34))^$B$39 -> 0.043116965 | F11: =(накопительные!F11/SUM(накопительные!F$2:F$34))^$B$39 -> 0.034302108 | G11: =(накопительные!G11/SUM(накопительные!G$2:G$34))^$B$39 -> 0.028872907 | H11: =(накопительные!H11/SUM(накопительные!H$2:H$34))^$B$39 -> 0.027266845 | I11: =(накопительные!I11/SUM(накопительные!I$2:I$34))^$B$39 -> 0.025111726 | ... T11: =(накопительные!T11/SUM(накопительные!T$2:T$34))^$B$39 -> 0.0089452219
A12: Кислица | B12: =(накопительные!B12/SUM(накопительные!B$2:B$34))^$B$39 -> 0 | C12: =(накопительные!C12/SUM(накопительные!C$2:C$34))^$B$39 -> 0 | D12: =(накопительные!D12/SUM(накопительные!D$2:D$34))^$B$39 -> 0 | E12: =(накопительные!E12/SUM(накопительные!E$2:E$34))^$B$39 -> 0 | F12: =(накопительные!F12/SUM(накопительные!F$2:F$34))^$B$39 -> 0.013097169 | G12: =(накопительные!G12/SUM(накопительные!G$2:G$34))^$B$39 -> 0.015223896 | H12: =(накопительные!H12/SUM(накопительные!H$2:H$34))^$B$39 -> 0.015250947 | I12: =(накопительные!I12/SUM(накопительные!I$2:I$34))^$B$39 -> 0.016173654 | ... T12: =(накопительные!T12/SUM(накопительные!T$2:T$34))^$B$39 -> 0.013114605
A13: Коротконожка | B13: =(накопительные!B13/SUM(накопительные!B$2:B$34))^$B$39 -> 0 | C13: =(накопительные!C13/SUM(накопительные!C$2:C$34))^$B$39 -> 0 | D13: =(накопительные!D13/SUM(накопительные!D$2:D$34))^$B$39 -> 0 | E13: =(накопительные!E13/SUM(накопительные!E$2:E$34))^$B$39 -> 0 | F13: =(накопительные!F13/SUM(накопительные!F$2:F$34))^$B$39 -> 0.017462891 | G13: =(накопительные!G13/SUM(накопительные!G$2:G$34))^$B$39 -> 0.027298021 | H13: =(накопительные!H13/SUM(накопительные!H$2:H$34))^$B$39 -> 0.024031796 | I13: =(накопительные!I13/SUM(накопительные!I$2:I$34))^$B$39 -> 0.03617791 | ... T13: =(накопительные!T13/SUM(накопительные!T$2:T$34))^$B$39 -> 0.021453371
... A34: Клевер люпиновидный | B34: =(накопительные!B34/SUM(накопительные!B$2:B$34))^$B$39 -> 0 | C34: =(накопительные!C34/SUM(накопительные!C$2:C$34))^$B$39 -> 0 | D34: =(накопительные!D34/SUM(накопительные!D$2:D$34))^$B$39 -> 0 | E34: =(накопительные!E34/SUM(накопительные!E$2:E$34))^$B$39 -> 0 | F34: =(накопительные!F34/SUM(накопительные!F$2:F$34))^$B$39 -> 0 | G34: =(накопительные!G34/SUM(накопительные!G$2:G$34))^$B$39 -> 0 | H34: =(накопительные!H34/SUM(накопительные!H$2:H$34))^$B$39 -> 0 | I34: =(накопительные!I34/SUM(накопительные!I$2:I$34))^$B$39 -> 0 | ... T34: =(накопительные!T34/SUM(накопительные!T$2:T$34))^$B$39 -> 0.0053822945
A36: M(q) | B36: =SUM(B2:B34) -> 1 | C36: =SUM(C2:C34) -> 1 | D36: =SUM(D2:D34) -> 1 | E36: =SUM(E2:E34) -> 1 | F36: =SUM(F2:F34) -> 1 | G36: =SUM(G2:G34) -> 1 | H36: =SUM(H2:H34) -> 1 | I36: =SUM(I2:I34) -> 1 | ... T36: =SUM(T2:T34) -> 1
A37: t(q) | B37: =LN(B36)/LN(SUM(накопительные!B2:B34)) -> -7.7180591e-17 | C37: =LN(C36)/LN(SUM(накопительные!C2:C34)) -> 0 | D37: =LN(D36)/LN(SUM(накопительные!D2:D34)) -> 4.8719001e-17 | E37: =LN(E36)/LN(SUM(накопительные!E2:E34)) -> 0 | F37: =LN(F36)/LN(SUM(накопительные!F2:F34)) -> -4.3732841e-17 | G37: =LN(G36)/LN(SUM(накопительные!G2:G34)) -> -4.2297436e-17 | H37: =LN(H36)/LN(SUM(накопительные!H2:H34)) -> -1.0323745e-16 | I37: =LN(I36)/LN(SUM(накопительные!I2:I34)) -> -2.0336091e-17 | ... T37: =LN(T36)/LN(SUM(накопительные!T2:T34)) -> 3.4204974e-17
A39: q | B39: 1

Sheet q = 2
A1: № | B1: 1 | C1: 2 | D1: 3 | E1: 4 | F1: 5 | G1: 6 | H1: 7 | I1: 8 | J1: 9 | K1: 10 | L1: 11 | M1: 12 | N1: 13 | O1: 14 | P1: 15 | Q1: 16 | R1: 17 | S1: 18 | T1: 19
A2: Брусника | B2: =(накопительные!B2/SUM(накопительные!B$2:B$34))^$B$39 -> 0.061378947 | C2: =(накопительные!C2/SUM(накопительные!C$2:C$34))^$B$39 -> 0.0051077622 | D2: =(накопительные!D2/SUM(накопительные!D$2:D$34))^$B$39 -> 0.0051599876 | E2: =(накопительные!E2/SUM(накопительные!E$2:E$34))^$B$39 -> 0.0028837136 | F2: =(накопительные!F2/SUM(накопительные!F$2:F$34))^$B$39 -> 0.001825145 | G2: =(накопительные!G2/SUM(накопительные!G$2:G$34))^$B$39 -> 0.0012931139 | H2: =(накопительные!H2/SUM(накопительные!H$2:H$34))^$B$39 -> 0.0010021827 | I2: =(накопительные!I2/SUM(накопительные!I$2:I$34))^$B$39 -> 0.00085002215 | ... T2: =(накопительные!T2/SUM(накопительные!T$2:T$34))^$B$39 -> 0.00014896011
A3: Вейник | B3: =(накопительные!B3/SUM(накопительные!B$2:B$34))^$B$39 -> 0.17833501 | C3: =(накопительные!C3/SUM(накопительные!C$2:C$34))^$B$39 -> 0.39766315 | D3: =(накопительные!D3/SUM(накопительные!D$2:D$34))^$B$39 -> 0.27712452 | E3: =(накопительные!E3/SUM(накопительные!E$2:E$34))^$B$39 -> 0.29685242 | F3: =(накопительные!F3/SUM(накопительные!F$2:F$34))^$B$39 -> 0.22289894 | G3: =(накопительные!G3/SUM(накопительные!G$2:G$34))^$B$39 -> 0.18305047 | H3: =(накопительные!H3/SUM(накопительные!H$2:H$34))^$B$39 -> 0.21230298 | I3: =(накопительные!I3/SUM(накопительные!I$2:I$34))^$B$39 -> 0.19631368 | ... T3: =(накопительные!T3/SUM(накопительные!T$2:T$34))^$B$39 -> 0.12554391
A4: Вероника дубравная | B4: =(накопительные!B4/SUM(накопительные!B$2:B$34))^$B$39 -> 0 | C4: =(накопительные!C4/SUM(накопительные!C$2:C$34))^$B$39 -> 0 | D4: =(накопительные!D4/SUM(накопительные!D$2:D$34))^$B$39 -> 0 | E4: =(накопительные!E4/SUM(накопительные!E$2:E$34))^$B$39 -> 0 | F4: =(накопительные!F4/SUM(накопительные!F$2:F$34))^$B$39 -> 0 | G4: =(накопительные!G4/SUM(накопительные!G$2:G$34))^$B$39 -> 6.889626e-08 | H4: =(накопительные!H4/SUM(накопительные!H$2:H$34))^$B$39 -> 1.0465545e-07 | I4: =(накопительные!I4/SUM(накопительные!I$2:I$34))^$B$39 -> 1.1593887e-07 | ... T4: =(накопительные!T4/SUM(накопительные!T$2:T$34))^$B$39 -> 1.8021639e-07
A5: Герань | B5: =(накопительные!B5/SUM(накопительные!B$2:B$34))^$B$39 -> 2.8533601e-06 | C5: =(накопительные!C5/SUM(накопительные!C$2:C$34))^$B$39 -> 1.0388336e-05 | D5: =(накопительные!D5/SUM(накопительные!D$2:D$34))^$B$39 -> 5.8173231e-06 | E5: =(накопительные!E5/SUM(накопительные!E$2:E$34))^$B$39 -> 6.6926615e-06 | F5: =(накопительные!F5/SUM(накопительные!F$2:F$34))^$B$39 -> 0.00014488748 | G5: =(накопительные!G5/SUM(накопительные!G$2:G$34))^$B$39 -> 0.00019061942 | H5: =(накопительные!H5/SUM(накопительные!H$2:H$34))^$B$39 -> 0.00015918094 | I5: =(накопительные!I5/SUM(накопительные!I$2:I$34))^$B$39 -> 0.00013799624 | ... T5: =(накопительные!T5/SUM(накопительные!T$2:T$34))^$B$39 -> 7.5735936e-05
A6: Горошик лесной | B6: =(накопительные!B6/SUM(накопительные!B$2:B$34))^$B$39 -> 0 | C6: =(накопительные!C6/SUM(накопительные!C$2:C$34))^$B$39 -> 0 | D6: =(накопительные!D6/SUM(накопительные!D$2:D$34))^$B$39 -> 0 | E6: =(накопительные!E6/SUM(накопительные!E$2:E$34))^$B$39 -> 0 | F6: =(накопительные!F6/SUM(накопительные!F$2:F$34))^$B$39 -> 3.8897012e-09 | G6: =(накопительные!G6/SUM(накопительные!G$2:G$34))^$B$39 -> 2.7558504e-09 | H6: =(накопительные!H6/SUM(накопительные!H$2:H$34))^$B$39 -> 2.1358255e-09 | I6: =(накопительные!I6/SUM(накопительные!I$2:I$34))^$B$39 -> 6.5215616e-08 | ... T6: =(накопительные!T6/SUM(накопительные!T$2:T$34))^$B$39 -> 4.2516355e-06
A7: Грушанка | B7: =(накопительные!B7/SUM(накопительные!B$2:B$34))^$B$39 -> 0 | C7: =(накопительные!C7/SUM(накопительные!C$2:C$34))^$B$39 -> 0 | D7: =(накопительные!D7/SUM(накопительные!D$2:D$34))^$B$39 -> 1.099683e-06 | E7: =(накопительные!E7/SUM(накопительные!E$2:E$34))^$B$39 -> 6.1456947e-07 | F7: =(накопительные!F7/SUM(накопительные!F$2:F$34))^$B$39 -> 3.8897012e-07 | G7: =(накопительные!G7/SUM(накопительные!G$2:G$34))^$B$39 -> 2.7558504e-07 | H7: =(накопительные!H7/SUM(накопительные!H$2:H$34))^$B$39 -> 3.0755887e-07 | I7: =(накопительные!I7/SUM(накопительные!I$2:I$34))^$B$39 -> 2.6086246e-07 | ... T7: =(накопительные!T7/SUM(накопительные!T$2:T$34))^$B$39 -> 8.8932189e-05
A8: Звездчатка жестколистная | B8: =(накопительные!B8/SUM(накопительные!B$2:B$34))^$B$39 -> 0 | C8: =(накопительные!C8/SUM(накопительные!C$2:C$34))^$B$39 -> 0 | D8: =(накопительные!D8/SUM(накопительные!D$2:D$34))^$B$39 -> 0 | E8: =(накопительные!E8/SUM(накопительные!E$2:E$34))^$B$39 -> 0 | F8: =(накопительные!F8/SUM(накопительные!F$2:F$34))^$B$39 -> 0 | G8: =(накопительные!G8/SUM(накопительные!G$2:G$34))^$B$39 -> 6.889626e-06 | H8: =(накопительные!H8/SUM(накопительные!H$2:H$34))^$B$39 -> 1.5431339e-05 | I8: =(накопительные!I8/SUM(накопительные!I$2:I$34))^$B$39 -> 1.6349193e-05 | ... T8: =(накопительные!T8/SUM(накопительные!T$2:T$34))^$B$39 -> 0.00013985159
A9: Земляника | B9: =(накопительные!B9/SUM(накопительные!B$2:B$34))^$B$39 -> 0 | C9: =(накопительные!C9/SUM(накопительные!C$2:C$34))^$B$39 -> 0 | D9: =(накопительные!D9/SUM(накопительные!D$2:D$34))^$B$39 -> 0 | E9: =(накопительные!E9/SUM(накопительные!E$2:E$34))^$B$39 -> 0 | F9: =(накопительные!F9/SUM(накопительные!F$2:F$34))^$B$39 -> 0 | G9: =(накопительные!G9/SUM(накопительные!G$2:G$34))^$B$39 -> 0 | H9: =(накопительные!H9/SUM(накопительные!H$2:H$34))^$B$39 -> 0 | I9: =(накопительные!I9/SUM(накопительные!I$2:I$34))^$B$39 -> 0 | ... T9: =(накопительные!T9/SUM(накопительные!T$2:T$34))^$B$39 -> 4.4502414e-05
A10: Золотарник | B10: =(накопительные!B10/SUM(накопительные!B$2:B$34))^$B$39 -> 0.00019815001 | C10: =(накопительные!C10/SUM(накопительные!C$2:C$34))^$B$39 -> 3.9766315e-05 | D10: =(накопительные!D10/SUM(накопительные!D$2:D$34))^$B$39 -> 0.00060729994 | E10: =(накопительные!E10/SUM(накопительные!E$2:E$34))^$B$39 -> 0.00035399201 | F10: =(накопительные!F10/SUM(накопительные!F$2:F$34))^$B$39 -> 0.00022404679 | G10: =(накопительные!G10/SUM(накопительные!G$2:G$34))^$B$39 -> 0.00028219908 | H10: =(накопительные!H10/SUM(накопительные!H$2:H$34))^$B$39 -> 0.00021870853 | I10: =(накопительные!I10/SUM(накопительные!I$2:I$34))^$B$39 -> 0.0001855022 | ... T10: =(накопительные!T10/SUM(накопительные!T$2:T$34))^$B$39 -> 0.00012930066
A11: Иван-чай | B11: =(накопительные!B11/SUM(накопительные!B$2:B$34))^$B$39 -> 0.00079260003 | C11: =(накопительные!C11/SUM(накопительные!C$2:C$34))^$B$39 -> 0.00078550745 | D11: =(накопительные!D11/SUM(накопительные!D$2:D$34))^$B$39 -> 0.0029735429 | E11: =(накопительные!E11/SUM(накопительные!E$2:E$34))^$B$39 -> 0.0018590726 | F11: =(накопительные!F11/SUM(накопительные!F$2:F$34))^$B$39 -> 0.0011766346 | G11: =(накопительные!G11/SUM(накопительные!G$2:G$34))^$B$39 -> 0.00083364474 | H11: =(накопительные!H11/SUM(накопительные!H$2:H$34))^$B$39 -> 0.00074348086 | I11: =(накопительные!I11/SUM(накопительные!I$2:I$34))^$B$39 -> 0.00063059878 | ... T11: =(накопительные!T11/SUM(накопительные!T$2:T$34))^$B$39 -> 8.0016995e-05
A12: Кислица | B12: =(накопительные!B12/SUM(накопительные!B$2:B$34))^$B$39 -> 0 | C12: =(накопительные!C12/SUM(накопительные!C$2:C$34))^$B$39 -> 0 | D12: =(накопительные!D12/SUM(накопительные!D$2:D$34))^$B$39 -> 0 | E12: =(накопительные!E12/SUM(накопительные!E$2:E$34))^$B$39 -> 0 | F12: =(накопительные!F12/SUM(накопительные!F$2:F$34))^$B$39 -> 0.00017153582 | G12: =(накопительные!G12/SUM(накопительные!G$2:G$34))^$B$39 -> 0.00023176702 | H12: =(накопительные!H12/SUM(накопительные!H$2:H$34))^$B$39 -> 0.0002325914 | I12: =(накопительные!I12/SUM(накопительные!I$2:I$34))^$B$39 -> 0.00026158708 | ... T12: =(накопительные!T12/SUM(накопительные!T$2:T$34))^$B$39 -> 0.00017199286
A13: Коротконожка | B13: =(накопительные!B13/SUM(накопительные!B$2:B$34))^$B$39 -> 0 | C13: =(накопительные!C13/SUM(накопительные!C$2:C$34))^$B$39 -> 0 | D13: =(накопительные!D13/SUM(накопительные!D$2:D$34))^$B$39 -> 0 | E13: =(накопительные!E13/SUM(накопительные!E$2:E$34))^$B$39 -> 0 | F13: =(накопительные!F13/SUM(накопительные!F$2:F$34))^$B$39 -> 0.00030495257 | G13: =(накопительные!G13/SUM(накопительные!G$2:G$34))^$B$39 -> 0.00074518194 | H13: =(накопительные!H13/SUM(накопительные!H$2:H$34))^$B$39 -> 0.00057752721 | I13: =(накопительные!I13/SUM(накопительные!I$2:I$34))^$B$39 -> 0.0013088412 | ... T13: =(накопительные!T13/SUM(накопительные!T$2:T$34))^$B$39 -> 0.00046024713
... A34: Клевер люпиновидный | B34: =(накопительные!B34/SUM(накопительные!B$2:B$34))^$B$39 -> 0 | C34: =(накопительные!C34/SUM(накопительные!C$2:C$34))^$B$39 -> 0 | D34: =(накопительные!D34/SUM(накопительные!D$2:D$34))^$B$39 -> 0 | E34: =(накопительные!E34/SUM(накопительные!E$2:E$34))^$B$39 -> 0 | F34: =(накопительные!F34/SUM(накопительные!F$2:F$34))^$B$39 -> 0 | G34: =(накопительные!G34/SUM(накопительные!G$2:G$34))^$B$39 -> 0 | H34: =(накопительные!H34/SUM(накопительные!H$2:H$34))^$B$39 -> 0 | I34: =(накопительные!I34/SUM(накопительные!I$2:I$34))^$B$39 -> 0 | ... T34: =(накопительные!T34/SUM(накопительные!T$2:T$34))^$B$39 -> 2.8969094e-05
A36: M(q) | B36: =SUM(B2:B34) -> 0.26733385 | C36: =SUM(C2:C34) -> 0.42768795 | D36: =SUM(D2:D34) -> 0.32066886 | E36: =SUM(E2:E34) -> 0.34461078 | F36: =SUM(F2:F34) -> 0.26550998 | G36: =SUM(G2:G34) -> 0.22579123 | H36: =SUM(H2:H34) -> 0.24952859 | I36: =SUM(I2:I34) -> 0.23355141 | ... T36: =SUM(T2:T34) -> 0.19967755
A37: t(q) | B37: =LN(B36)/LN(SUM(накопительные!B2:B34)) -> -0.45856119 | C37: =LN(C36)/LN(SUM(накопительные!C2:C34)) -> -0.19901914 | D37: =LN(D36)/LN(SUM(накопительные!D2:D34)) -> -0.24954614 | E37: =LN(E36)/LN(SUM(накопительные!E2:E34)) -> -0.21972168 | F37: =LN(F36)/LN(SUM(накопительные!F2:F34)) -> -0.26118286 | G37: =LN(G36)/LN(SUM(накопительные!G2:G34)) -> -0.2834777 | H37: =LN(H36)/LN(SUM(накопительные!H2:H34)) -> -0.25816858 | I37: =LN(I36)/LN(SUM(накопительные!I2:I34)) -> -0.26639564 | ... T37: =LN(T36)/LN(SUM(накопительные!T2:T34)) -> -0.24817525
A39: q | B39: 2

Sheet q = 3
A1: № | B1: 1 | C1: 2 | D1: 3 | E1: 4 | F1: 5 | G1: 6 | H1: 7 | I1: 8 | J1: 9 | K1: 10 | L1: 11 | M1: 12 | N1: 13 | O1: 14 | P1: 15 | Q1: 16 | R1: 17 | S1: 18 | T1: 19
A2: Брусника | B2: =(накопительные!B2/SUM(накопительные!B$2:B$34))^$B$39 -> 0.015206496 | C2: =(накопительные!C2/SUM(накопительные!C$2:C$34))^$B$39 -> 0.00036504466 | D2: =(накопительные!D2/SUM(накопительные!D$2:D$34))^$B$39 -> 0.00037065767 | E2: =(накопительные!E2/SUM(накопительные!E$2:E$34))^$B$39 -> 0.00015485605 | F2: =(накопительные!F2/SUM(накопительные!F$2:F$34))^$B$39 -> 7.7973329e-05 | G2: =(накопительные!G2/SUM(накопительные!G$2:G$34))^$B$39 -> 4.6500237e-05 | H2: =(накопительные!H2/SUM(накопительные!H$2:H$34))^$B$39 -> 3.1726369e-05 | I2: =(накопительные!I2/SUM(накопительные!I$2:I$34))^$B$39 -> 2.4782514e-05 | ... T2: =(накопительные!T2/SUM(накопительные!T$2:T$34))^$B$39 -> 1.8180464e-06
A3: Вейник | B3: =(накопительные!B3/SUM(накопительные!B$2:B$34))^$B$39 -> 0.075310392 | C3: =(накопительные!C3/SUM(накопительные!C$2:C$34))^$B$39 -> 0.25076852 | D3: =(накопительные!D3/SUM(накопительные!D$2:D$34))^$B$39 -> 0.1458856 | E3: =(накопительные!E3/SUM(накопительные!E$2:E$34))^$B$39 -> 0.16173756 | F3: =(накопительные!F3/SUM(накопительные!F$2:F$34))^$B$39 -> 0.10523544 | G3: =(накопительные!G3/SUM(накопительные!G$2:G$34))^$B$39 -> 0.078317043 | H3: =(накопительные!H3/SUM(накопительные!H$2:H$34))^$B$39 -> 0.097821457 | I3: =(накопительные!I3/SUM(накопительные!I$2:I$34))^$B$39 -> 0.086981289 | ... T3: =(накопительные!T3/SUM(накопительные!T$2:T$34))^$B$39 -> 0.044482937
A4: Вероника дубравная | B4: =(накопительные!B4/SUM(накопительные!B$2:B$34))^$B$39 -> 0 | C4: =(накопительные!C4/SUM(накопительные!C$2:C$34))^$B$39 -> 0 | D4: =(накопительные!D4/SUM(накопительные!D$2:D$34))^$B$39 -> 0 | E4: =(накопительные!E4/SUM(накопительные!E$2:E$34))^$B$39 -> 0 | F4: =(накопительные!F4/SUM(накопительные!F$2:F$34))^$B$39 -> 0 | G4: =(накопительные!G4/SUM(накопительные!G$2:G$34))^$B$39 -> 1.8083957e-11 | H4: =(накопительные!H4/SUM(накопительные!H$2:H$34))^$B$39 -> 3.3856555e-11 | I4: =(накопительные!I4/SUM(накопительные!I$2:I$34))^$B$39 -> 3.9476952e-11 | ... T4: =(накопительные!T4/SUM(накопительные!T$2:T$34))^$B$39 -> 7.6505281e-11
A5: Герань | B5: =(накопительные!B5/SUM(накопительные!B$2:B$34))^$B$39 -> 4.8198651e-09 | C5: =(накопительные!C5/SUM(накопительные!C$2:C$34))^$B$39 -> 3.3482585e-08 | D5: =(накопительные!D5/SUM(накопительные!D$2:D$34))^$B$39 -> 1.4030876e-08 | E5: =(накопительные!E5/SUM(накопительные!E$2:E$34))^$B$39 -> 1.7314035e-08 | F5: =(накопительные!F5/SUM(накопительные!F$2:F$34))^$B$39 -> 1.7439992e-06 | G5: =(накопительные!G5/SUM(накопительные!G$2:G$34))^$B$39 -> 2.6317868e-06 | H5: =(накопительные!H5/SUM(накопительные!H$2:H$34))^$B$39 -> 2.008337e-06 | I5: =(накопительные!I5/SUM(накопительные!I$2:I$34))^$B$39 -> 1.6210668e-06 | ... T5: =(накопительные!T5/SUM(накопительные!T$2:T$34))^$B$39 -> 6.5910256e-07
A6: Горошик лесной | B6: =(накопительные!B6/SUM(накопительные!B$2:B$34))^$B$39 -> 0 | C6: =(накопительные!C6/SUM(накопительные!C$2:C$34))^$B$39 -> 0 | D6: =(накопительные!D6/SUM(накопительные!D$2:D$34))^$B$39 -> 0 | E6: =(накопительные!E6/SUM(накопительные!E$2:E$34))^$B$39 -> 0 | F6: =(накопительные!F6/SUM(накопительные!F$2:F$34))^$B$39 -> 2.4259082e-13 | G6: =(накопительные!G6/SUM(накопительные!G$2:G$34))^$B$39 -> 1.4467166e-13 | H6: =(накопительные!H6/SUM(накопительные!H$2:H$34))^$B$39 -> 9.8707159e-14 | I6: =(накопительные!I6/SUM(накопительные!I$2:I$34))^$B$39 -> 1.6654339e-11 | ... T6: =(накопительные!T6/SUM(накопительные!T$2:T$34))^$B$39 -> 8.7666576e-09
A7: Грушанка | B7: =(накопительные!B7/SUM(накопительные!B$2:B$34))^$B$39 -> 0 | C7: =(накопительные!C7/SUM(накопительные!C$2:C$34))^$B$39 -> 0 | D7: =(накопительные!D7/SUM(накопительные!D$2:D$34))^$B$39 -> 1.1531911e-09 | E7: =(накопительные!E7/SUM(накопительные!E$2:E$34))^$B$39 -> 4.8178854e-10 | F7: =(накопительные!F7/SUM(накопительные!F$2:F$34))^$B$39 -> 2.4259082e-10 | G7: =(накопительные!G7/SUM(накопительные!G$2:G$34))^$B$39 -> 1.4467166e-10 | H7: =(накопительные!H7/SUM(накопительные!H$2:H$34))^$B$39 -> 1.7056597e-10 | I7: =(накопительные!I7/SUM(накопительные!I$2:I$34))^$B$39 -> 1.3323471e-10 | ... T7: =(накопительные!T7/SUM(накопительные!T$2:T$34))^$B$39 -> 8.3866491e-07
A8: Звездчатка жестколистная | B8: =(накопительные!B8/SUM(накопительные!B$2:B$34))^$B$39 -> 0 | C8: =(накопительные!C8/SUM(накопительные!C$2:C$34))^$B$39 -> 0 | D8: =(накопительные!D8/SUM(накопительные!D$2:D$34))^$B$39 -> 0 | E8: =(накопительные!E8/SUM(накопительные!E$2:E$34))^$B$39 -> 0 | F8: =(накопительные!F8/SUM(накопительные!F$2:F$34))^$B$39 -> 0 | G8: =(накопительные!G8/SUM(накопительные!G$2:G$34))^$B$39 -> 1.8083957e-08 | H8: =(накопительные!H8/SUM(накопительные!H$2:H$34))^$B$39 -> 6.0618534e-08 | I8: =(накопительные!I8/SUM(накопительные!I$2:I$34))^$B$39 -> 6.6106546e-08 | ... T8: =(накопительные!T8/SUM(накопительные!T$2:T$34))^$B$39 -> 1.6538691e-06
A9: Земляника | B9: =(накопительные!B9/SUM(накопительные!B$2:B$34))^$B$39 -> 0 | C9: =(накопительные!C9/SUM(накопительные!C$2:C$34))^$B$39 -> 0 | D9: =(накопительные!D9/SUM(накопительные!D$2:D$34))^$B$39 -> 0 | E9: =(накопительные!E9/SUM(накопительные!E$2:E$34))^$B$39 -> 0 | F9: =(накопительные!F9/SUM(накопительные!F$2:F$34))^$B$39 -> 0 | G9: =(накопительные!G9/SUM(накопительные!G$2:G$34))^$B$39 -> 0 | H9: =(накопительные!H9/SUM(накопительные!H$2:H$34))^$B$39 -> 0 | I9: =(накопительные!I9/SUM(накопительные!I$2:I$34))^$B$39 -> 0 | ... T9: =(накопительные!T9/SUM(накопительные!T$2:T$34))^$B$39 -> 2.9687618e-07
A10: Золотарник | B10: =(накопительные!B10/SUM(накопительные!B$2:B$34))^$B$39 -> 2.7892738e-06 | C10: =(накопительные!C10/SUM(накопительные!C$2:C$34))^$B$39 -> 2.5076852e-07 | D10: =(накопительные!D10/SUM(накопительные!D$2:D$34))^$B$39 -> 1.496597e-05 | E10: =(накопительные!E10/SUM(накопительные!E$2:E$34))^$B$39 -> 6.6602448e-06 | F10: =(накопительные!F10/SUM(накопительные!F$2:F$34))^$B$39 -> 3.3535755e-06 | G10: =(накопительные!G10/SUM(накопительные!G$2:G$34))^$B$39 -> 4.7406008e-06 | H10: =(накопительные!H10/SUM(накопительные!H$2:H$34))^$B$39 -> 3.2344362e-06 | I10: =(накопительные!I10/SUM(накопительные!I$2:I$34))^$B$39 -> 2.5265249e-06 | ... T10: =(накопительные!T10/SUM(накопительные!T$2:T$34))^$B$39 -> 1.4702836e-06
A11: Иван-чай | B11: =(накопительные!B11/SUM(накопительные!B$2:B$34))^$B$39 -> 2.231419e-05 | C11: =(накопительные!C11/SUM(накопительные!C$2:C$34))^$B$39 -> 2.2015343e-05 | D11: =(накопительные!D11/SUM(накопительные!D$2:D$34))^$B$39 -> 0.00016214789 | E11: =(накопительные!E11/SUM(накопительные!E$2:E$34))^$B$39 -> 8.0157569e-05 | F11: =(накопительные!F11/SUM(накопительные!F$2:F$34))^$B$39 -> 4.0361048e-05 | G11: =(накопительные!G11/SUM(накопительные!G$2:G$34))^$B$39 -> 2.4069747e-05 | H11: =(накопительные!H11/SUM(накопительные!H$2:H$34))^$B$39 -> 2.0272378e-05 | I11: =(накопительные!I11/SUM(накопительные!I$2:I$34))^$B$39 -> 1.5835424e-05 | ... T11: =(накопительные!T11/SUM(накопительные!T$2:T$34))^$B$39 -> 7.1576977e-07
A12: Кислица | B12: =(накопительные!B12/SUM(накопительные!B$2:B$34))^$B$39 -> 0 | C12: =(накопительные!C12/SUM(накопительные!C$2:C$34))^$B$39 -> 0 | D12: =(накопительные!D12/SUM(накопительные!D$2:D$34))^$B$39 -> 0 | E12: =(накопительные!E12/SUM(накопительные!E$2:E$34))^$B$39 -> 0 | F12: =(накопительные!F12/SUM(накопительные!F$2:F$34))^$B$39 -> 2.2466336e-06 | G12: =(накопительные!G12/SUM(накопительные!G$2:G$34))^$B$39 -> 3.528397e-06 | H12: =(накопительные!H12/SUM(накопительные!H$2:H$34))^$B$39 -> 3.5472392e-06 | I12: =(накопительные!I12/SUM(накопительные!I$2:I$34))^$B$39 -> 4.230819e-06 | ... T12: =(накопительные!T12/SUM(накопительные!T$2:T$34))^$B$39 -> 2.2556185e-06
A13: Коротконожка | B13: =(накопительные!B13/SUM(накопительные!B$2:B$34))^$B$39 -> 0 | C13: =(накопительные!C13/SUM(накопительные!C$2:C$34))^$B$39 -> 0 | D13: =(накопительные!D13/SUM(накопительные!D$2:D$34))^$B$39 -> 0 | E13: =(накопительные!E13/SUM(накопительные!E$2:E$34))^$B$39 -> 0 | F13: =(накопительные!F13/SUM(накопительные!F$2:F$34))^$B$39 -> 5.3253537e-06 | G13: =(накопительные!G13/SUM(накопительные!G$2:G$34))^$B$39 -> 2.0341992e-05 | H13: =(накопительные!H13/SUM(накопительные!H$2:H$34))^$B$39 -> 1.3879016e-05 | I13: =(накопительные!I13/SUM(накопительные!I$2:I$34))^$B$39 -> 4.7351139e-05 | ... T13: =(накопительные!T13/SUM(накопительные!T$2:T$34))^$B$39 -> 9.8738526e-06
... A34: Клевер люпиновидный | B34: =(накопительные!B34/SUM(накопительные!B$2:B$34))^$B$39 -> 0 | C34: =(накопительные!C34/SUM(накопительные!C$2:C$34))^$B$39 -> 0 | D34: =(накопительные!D34/SUM(накопительные!D$2:D$34))^$B$39 -> 0 | E34: =(накопительные!E34/SUM(накопительные!E$2:E$34))^$B$39 -> 0 | F34: =(накопительные!F34/SUM(накопительные!F$2:F$34))^$B$39 -> 0 | G34: =(накопительные!G34/SUM(накопительные!G$2:G$34))^$B$39 -> 0 | H34: =(накопительные!H34/SUM(накопительные!H$2:H$34))^$B$39 -> 0 | I34: =(накопительные!I34/SUM(накопительные!I$2:I$34))^$B$39 -> 0 | ... T34: =(накопительные!T34/SUM(накопительные!T$2:T$34))^$B$39 -> 1.559202e-07
A36: M(q) | B36: =SUM(B2:B34) -> 0.093756025 | C36: =SUM(C2:C34) -> 0.25423389 | D36: =SUM(D2:D34) -> 0.15189 | E36: =SUM(E2:E34) -> 0.16975003 | F36: =SUM(F2:F34) -> 0.11109662 | G36: =SUM(G2:G34) -> 0.083488097 | H36: =SUM(H2:H34) -> 0.10205968 | I36: =SUM(I2:I34) -> 0.09088671 | ... T36: =SUM(T2:T34) -> 0.05785703
A37: t(q) | B37: =LN(B36)/LN(SUM(накопительные!B2:B34)) -> -0.8227673 | C37: =LN(C36)/LN(SUM(накопительные!C2:C34)) -> -0.32089617 | D37: =LN(D36)/LN(SUM(накопительные!D2:D34)) -> -0.41350146 | E37: =LN(E36)/LN(SUM(накопительные!E2:E34)) -> -0.3657619 | F37: =LN(F36)/LN(SUM(накопительные!F2:F34)) -> -0.43278051 | G37: =LN(G36)/LN(SUM(накопительные!G2:G34)) -> -0.4729982 | H37: =LN(H36)/LN(SUM(накопительные!H2:H34)) -> -0.4244341 | I37: =LN(I36)/LN(SUM(накопительные!I2:I34)) -> -0.43927052 | ... T37: =LN(T36)/LN(SUM(накопительные!T2:T34)) -> -0.43899586
A39: q | B39: 3

Sheet q = -1
A1: № | B1: 1 | C1: 2 | D1: 3 | E1: 4 | F1: 5 | G1: 6 | H1: 7 | I1: 8 | J1: 9 | K1: 10 | L1: 11 | M1: 12 | N1: 13 | O1: 14 | P1: 15 | Q1: 16 | R1: 17 | S1: 18 | T1: 19
A2: Брусника | B2: =IF(накопительные!B2 = 0, 0,(накопительные!B2/SUM(накопительные!B$2:B$34))^$B$39) -> 4.0363636 | C2: =IF(накопительные!C2 = 0, 0,(накопительные!C2/SUM(накопительные!C$2:C$34))^$B$39) -> 13.992157 | D2: =IF(накопительные!D2 = 0, 0,(накопительные!D2/SUM(накопительные!D$2:D$34))^$B$39) -> 13.921168 | E2: =IF(накопительные!E2 = 0, 0,(накопительные!E2/SUM(накопительные!E$2:E$34))^$B$39) -> 18.621898 | F2: =IF(накопительные!F2 = 0, 0,(накопительные!F2/SUM(накопительные!F$2:F$34))^$B$39) -> 23.407299 | G2: =IF(накопительные!G2 = 0, 0,(накопительные!G2/SUM(накопительные!G$2:G$34))^$B$39) -> 27.808759 | H2: =IF(накопительные!H2 = 0, 0,(накопительные!H2/SUM(накопительные!H$2:H$34))^$B$39) -> 31.588321 | I2: =IF(накопительные!I2 = 0, 0,(накопительные!I2/SUM(накопительные!I$2:I$34))^$B$39) -> 34.29927 | ... T2: =IF(накопительные!T2 = 0, 0,(накопительные!T2/SUM(накопительные!T$2:T$34))^$B$39) -> 81.934161
A3: Вейник | B3: =IF(накопительные!B3 = 0, 0,(накопительные!B3/SUM(накопительные!B$2:B$34))^$B$39) -> 2.368 | C3: =IF(накопительные!C3 = 0, 0,(накопительные!C3/SUM(накопительные!C$2:C$34))^$B$39) -> 1.5857778 | D3: =IF(накопительные!D3 = 0, 0,(накопительные!D3/SUM(накопительные!D$2:D$34))^$B$39) -> 1.8996016 | E3: =IF(накопительные!E3 = 0, 0,(накопительные!E3/SUM(накопительные!E$2:E$34))^$B$39) -> 1.8353957 | F3: =IF(накопительные!F3 = 0, 0,(накопительные!F3/SUM(накопительные!F$2:F$34))^$B$39) -> 2.1180978 | G3: =IF(накопительные!G3 = 0, 0,(накопительные!G3/SUM(накопительные!G$2:G$34))^$B$39) -> 2.3373006 | H3: =IF(накопительные!H3 = 0, 0,(накопительные!H3/SUM(накопительные!H$2:H$34))^$B$39) -> 2.1703109 | I3: =IF(накопительные!I3 = 0, 0,(накопительные!I3/SUM(накопительные!I$2:I$34))^$B$39) -> 2.2569645 | ... T3: =IF(накопительные!T3 = 0, 0,(накопительные!T3/SUM(накопительные!T$2:T$34))^$B$39) -> 2.8222935
A4: Вероника дубравная | B4: =IF(накопительные!B4 = 0, 0,(накопительные!B4/SUM(накопительные!B$2:B$34))^$B$39) -> 0 | C4: =IF(накопительные!C4 = 0, 0,(накопительные!C4/SUM(накопительные!C$2:C$34))^$B$39) -> 0 | D4: =IF(накопительные!D4 = 0, 0,(накопительные!D4/SUM(накопительные!D$2:D$34))^$B$39) -> 0 | E4: =IF(накопительные!E4 = 0, 0,(накопительные!E4/SUM(накопительные!E$2:E$34))^$B$39) -> 0 | F4: =IF(накопительные!F4 = 0, 0,(накопительные!F4/SUM(накопительные!F$2:F$34))^$B$39) -> 0 | G4: =IF(накопительные!G4 = 0, 0,(накопительные!G4/SUM(накопительные!G$2:G$34))^$B$39) -> 3809.8 | H4: =IF(накопительные!H4 = 0, 0,(накопительные!H4/SUM(накопительные!H$2:H$34))^$B$39) -> 3091.1429 | I4: =IF(накопительные!I4 = 0, 0,(накопительные!I4/SUM(накопительные!I$2:I$34))^$B$39) -> 2936.875 | ... T4: =IF(накопительные!T4 = 0, 0,(накопительные!T4/SUM(накопительные!T$2:T$34))^$B$39) -> 2355.6071
A5: Герань | B5: =IF(накопительные!B5 = 0, 0,(накопительные!B5/SUM(накопительные!B$2:B$34))^$B$39) -> 592 | C5: =IF(накопительные!C5 = 0, 0,(накопительные!C5/SUM(накопительные!C$2:C$34))^$B$39) -> 310.26087 | D5: =IF(накопительные!D5 = 0, 0,(накопительные!D5/SUM(накопительные!D$2:D$34))^$B$39) -> 414.6087 | E5: =IF(накопительные!E5 = 0, 0,(накопительные!E5/SUM(накопительные!E$2:E$34))^$B$39) -> 386.54545 | F5: =IF(накопительные!F5 = 0, 0,(накопительные!F5/SUM(накопительные!F$2:F$34))^$B$39) -> 83.07772 | G5: =IF(накопительные!G5 = 0, 0,(накопительные!G5/SUM(накопительные!G$2:G$34))^$B$39) -> 72.429658 | H5: =IF(накопительные!H5 = 0, 0,(накопительные!H5/SUM(накопительные!H$2:H$34))^$B$39) -> 79.260073 | I5: =IF(накопительные!I5 = 0, 0,(накопительные!I5/SUM(накопительные!I$2:I$34))^$B$39) -> 85.126812 | ... T5: =IF(накопительные!T5 = 0, 0,(накопительные!T5/SUM(накопительные!T$2:T$34))^$B$39) -> 114.90767
A6: Горошик лесной | B6: =IF(накопительные!B6 = 0, 0,(накопительные!B6/SUM(накопительные!B$2:B$34))^$B$39) -> 0 | C6: =IF(накопительные!C6 = 0, 0,(накопительные!C6/SUM(накопительные!C$2:C$34))^$B$39) -> 0 | D6: =IF(накопительные!D6 = 0, 0,(накопительные!D6/SUM(накопительные!D$2:D$34))^$B$39) -> 0 | E6: =IF(накопительные!E6 = 0, 0,(накопительные!E6/SUM(накопительные!E$2:E$34))^$B$39) -> 0 | F6: =IF(накопительные!F6 = 0, 0,(накопительные!F6/SUM(накопительные!F$2:F$34))^$B$39) -> 16034 | G6: =IF(накопительные!G6 = 0, 0,(накопительные!G6/SUM(накопительные!G$2:G$34))^$B$39) -> 19049 | H6: =IF(накопительные!H6 = 0, 0,(накопительные!H6/SUM(накопительные!H$2:H$34))^$B$39) -> 21638 | I6: =IF(накопительные!I6 = 0, 0,(накопительные!I6/SUM(накопительные!I$2:I$34))^$B$39) -> 3915.8333 | ... T6: =IF(накопительные!T6 = 0, 0,(накопительные!T6/SUM(накопительные!T$2:T$34))^$B$39) -> 484.97794
A7: Грушанка | B7: =IF(накопительные!B7 = 0, 0,(накопительные!B7/SUM(накопительные!B$2:B$34))^$B$39) -> 0 | C7: =IF(накопительные!C7 = 0, 0,(накопительные!C7/SUM(накопительные!C$2:C$34))^$B$39) -> 0 | D7: =IF(накопительные!D7 = 0, 0,(накопительные!D7/SUM(накопительные!D$2:D$34))^$B$39) -> 953.6 | E7: =IF(накопительные!E7 = 0, 0,(накопительные!E7/SUM(накопительные!E$2:E$34))^$B$39) -> 1275.6 | F7: =IF(накопительные!F7 = 0, 0,(накопительные!F7/SUM(накопительные!F$2:F$34))^$B$39) -> 1603.4 | G7: =IF(накопительные!G7 = 0, 0,(накопительные!G7/SUM(накопительные!G$2:G$34))^$B$39) -> 1904.9 | H7: =IF(накопительные!H7 = 0, 0,(накопительные!H7/SUM(накопительные!H$2:H$34))^$B$39) -> 1803.1667 | I7: =IF(накопительные!I7 = 0, 0,(накопительные!I7/SUM(накопительные!I$2:I$34))^$B$39) -> 1957.9167 | ... T7: =IF(накопительные!T7 = 0, 0,(накопительные!T7/SUM(накопительные!T$2:T$34))^$B$39) -> 106.04019
A8: Звездчатка жестколистная | B8: =IF(накопительные!B8 = 0, 0,(накопительные!B8/SUM(накопительные!B$2:B$34))^$B$39) -> 0 | C8: =IF(накопительные!C8 = 0, 0,(накопительные!C8/SUM(накопительные!C$2:C$34))^$B$39) -> 0 | D8: =IF(накопительные!D8 = 0, 0,(накопительные!D8/SUM(накопительные!D$2:D$34))^$B$39) -> 0 | E8: =IF(накопительные!E8 = 0, 0,(накопительные!E8/SUM(накопительные!E$2:E$34))^$B$39) -> 0 | F8: =IF(накопительные!F8 = 0, 0,(накопительные!F8/SUM(накопительные!F$2:F$34))^$B$39) -> 0 | G8: =IF(накопительные!G8 = 0, 0,(накопительные!G8/SUM(накопительные!G$2:G$34))^$B$39) -> 380.98 | H8: =IF(накопительные!H8 = 0, 0,(накопительные!H8/SUM(накопительные!H$2:H$34))^$B$39) -> 254.56471 | I8: =IF(накопительные!I8 = 0, 0,(накопительные!I8/SUM(накопительные!I$2:I$34))^$B$39) -> 247.31579 | ... T8: =IF(накопительные!T8 = 0, 0,(накопительные!T8/SUM(накопительные!T$2:T$34))^$B$39) -> 84.560256
A9: Земляника | B9: =IF(накопительные!B9 = 0, 0,(накопительные!B9/SUM(накопительные!B$2:B$34))^$B$39) -> 0 | C9: =IF(накопительные!C9 = 0, 0,(накопительные!C9/SUM(накопительные!C$2:C$34))^$B$39) -> 0 | D9: =IF(накопительные!D9 = 0, 0,(накопительные!D9/SUM(накопительные!D$2:D$34))^$B$39) -> 0 | E9: =IF(накопительные!E9 = 0, 0,(накопительные!E9/SUM(накопительные!E$2:E$34))^$B$39) -> 0 | F9: =IF(накопительные!F9 = 0, 0,(накопительные!F9/SUM(накопительные!F$2:F$34))^$B$39) -> 0 | G9: =IF(накопительные!G9 = 0, 0,(накопительные!G9/SUM(накопительные!G$2:G$34))^$B$39) -> 0 | H9: =IF(накопительные!H9 = 0, 0,(накопительные!H9/SUM(накопительные!H$2:H$34))^$B$39) -> 0 | I9: =IF(накопительные!I9 = 0, 0,(накопительные!I9/SUM(накопительные!I$2:I$34))^$B$39) -> 0 | ... T9: =IF(накопительные!T9 = 0, 0,(накопительные!T9/SUM(накопительные!T$2:T$34))^$B$39) -> 149.90227
A10: Золотарник | B10: =IF(накопительные!B10 = 0, 0,(накопительные!B10/SUM(накопительные!B$2:B$34))^$B$39) -> 71.04 | C10: =IF(накопительные!C10 = 0, 0,(накопительные!C10/SUM(накопительные!C$2:C$34))^$B$39) -> 158.57778 | D10: =IF(накопительные!D10 = 0, 0,(накопительные!D10/SUM(накопительные!D$2:D$34))^$B$39) -> 40.578723 | E10: =IF(накопительные!E10 = 0, 0,(накопительные!E10/SUM(накопительные!E$2:E$34))^$B$39) -> 53.15 | F10: =IF(накопительные!F10 = 0, 0,(накопительные!F10/SUM(накопительные!F$2:F$34))^$B$39) -> 66.808333 | G10: =IF(накопительные!G10 = 0, 0,(накопительные!G10/SUM(накопительные!G$2:G$34))^$B$39) -> 59.528125 | H10: =IF(накопительные!H10 = 0, 0,(накопительные!H10/SUM(накопительные!H$2:H$34))^$B$39) -> 67.61875 | I10: =IF(накопительные!I10 = 0, 0,(накопительные!I10/SUM(накопительные!I$2:I$34))^$B$39) -> 73.421875 | ... T10: =IF(накопительные!T10 = 0, 0,(накопительные!T10/SUM(накопительные!T$2:T$34))^$B$39) -> 87.942667
A11: Иван-чай | B11: =IF(накопительные!B11 = 0, 0,(накопительные!B11/SUM(накопительные!B$2:B$34))^$B$39) -> 35.52 | C11: =IF(накопительные!C11 = 0, 0,(накопительные!C11/SUM(накопительные!C$2:C$34))^$B$39) -> 35.68 | D11: =IF(накопительные!D11 = 0, 0,(накопительные!D11/SUM(накопительные!D$2:D$34))^$B$39) -> 18.338462 | E11: =IF(накопительные!E11 = 0, 0,(накопительные!E11/SUM(накопительные!E$2:E$34))^$B$39) -> 23.192727 | F11: =IF(накопительные!F11 = 0, 0,(накопительные!F11/SUM(накопительные!F$2:F$34))^$B$39) -> 29.152727 | G11: =IF(накопительные!G11 = 0, 0,(накопительные!G11/SUM(накопительные!G$2:G$34))^$B$39) -> 34.634545 | H11: =IF(накопительные!H11 = 0, 0,(накопительные!H11/SUM(накопительные!H$2:H$34))^$B$39) -> 36.674576 | I11: =IF(накопительные!I11 = 0, 0,(накопительные!I11/SUM(накопительные!I$2:I$34))^$B$39) -> 39.822034 | ... T11: =IF(накопительные!T11 = 0, 0,(накопительные!T11/SUM(накопительные!T$2:T$34))^$B$39) -> 111.79153
A12: Кислица | B12: =IF(накопительные!B12 = 0, 0,(накопительные!B12/SUM(накопительные!B$2:B$34))^$B$39) -> 0 | C12: =IF(накопительные!C12 = 0, 0,(накопительные!C12/SUM(накопительные!C$2:C$34))^$B$39) -> 0 | D12: =IF(накопительные!D12 = 0, 0,(накопительные!D12/SUM(накопительные!D$2:D$34))^$B$39) -> 0 | E12: =IF(накопительные!E12 = 0, 0,(накопительные!E12/SUM(накопительные!E$2:E$34))^$B$39) -> 0 | F12: =IF(накопительные!F12 = 0, 0,(накопительные!F12/SUM(накопительные!F$2:F$34))^$B$39) -> 76.352381 | G12: =IF(накопительные!G12 = 0, 0,(накопительные!G12/SUM(накопительные!G$2:G$34))^$B$39) -> 65.686207 | H12: =IF(накопительные!H12 = 0, 0,(накопительные!H12/SUM(накопительные!H$2:H$34))^$B$39) -> 65.569697 | I12: =IF(накопительные!I12 = 0, 0,(накопительные!I12/SUM(накопительные!I$2:I$34))^$B$39) -> 61.828947 | ... T12: =IF(накопительные!T12 = 0, 0,(накопительные!T12/SUM(накопительные!T$2:T$34))^$B$39) -> 76.250867
A13: Коротконожка | B13: =IF(накопительные!B13 = 0, 0,(накопительные!B13/SUM(накопительные!B$2:B$34))^$B$39) -> 0 | C13: =IF(накопительные!C13 = 0, 0,(накопительные!C13/SUM(накопительные!C$2:C$34))^$B$39) -> 0 | D13: =IF(накопительные!D13 = 0, 0,(накопительные!D13/SUM(накопительные!D$2:D$34))^$B$39) -> 0 | E13: =IF(накопительные!E13 = 0, 0,(накопительные!E13/SUM(накопительные!E$2:E$34))^$B$39) -> 0 | F13: =IF(накопительные!F13 = 0, 0,(накопительные!F13/SUM(накопительные!F$2:F$34))^$B$39) -> 57.264286 | G13: =IF(накопительные!G13 = 0, 0,(накопительные!G13/SUM(накопительные!G$2:G$34))^$B$39) -> 36.632692 | H13: =IF(накопительные!H13 = 0, 0,(накопительные!H13/SUM(накопительные!H$2:H$34))^$B$39) -> 41.611538 | I13: =IF(накопительные!I13 = 0, 0,(накопительные!I13/SUM(накопительные!I$2:I$34))^$B$39) -> 27.641176 | ... T13: =IF(накопительные!T13 = 0, 0,(накопительные!T13/SUM(накопительные!T$2:T$34))^$B$39) -> 46.612721
... A34: Клевер люпиновидный | B34: =IF(накопительные!B34 = 0, 0,(накопительные!B34/SUM(накопительные!B$2:B$34))^$B$39) -> 0 | C34: =IF(накопительные!C34 = 0, 0,(накопительные!C34/SUM(накопительные!C$2:C$34))^$B$39) -> 0 | D34: =IF(накопительные!D34 = 0, 0,(накопительные!D34/SUM(накопительные!D$2:D$34))^$B$39) -> 0 | E34: =IF(накопительные!E34 = 0, 0,(накопительные!E34/SUM(накопительные!E$2:E$34))^$B$39) -> 0 | F34: =IF(накопительные!F34 = 0, 0,(накопительные!F34/SUM(накопительные!F$2:F$34))^$B$39) -> 0 | G34: =IF(накопительные!G34 = 0, 0,(накопительные!G34/SUM(накопительные!G$2:G$34))^$B$39) -> 0 | H34: =IF(накопительные!H34 = 0, 0,(накопительные!H34/SUM(накопительные!H$2:H$34))^$B$39) -> 0 | I34: =IF(накопительные!I34 = 0, 0,(накопительные!I34/SUM(накопительные!I$2:I$34))^$B$39) -> 0 | ... T34: =IF(накопительные!T34 = 0, 0,(накопительные!T34/SUM(накопительные!T$2:T$34))^$B$39) -> 185.79437
A36: M(q) | B36: =SUM(B2:B34) -> 2171.1966 | C36: =SUM(C2:C34) -> 5117.4351 | D36: =SUM(D2:D34) -> 4600.2467 | E36: =SUM(E2:E34) -> 4725.8371 | F36: =SUM(F2:F34) -> 38152.032 | G36: =SUM(G2:G34) -> 37364.023 | H36: =SUM(H2:H34) -> 35096.566 | I36: =SUM(I2:I34) -> 15096.797 | ... T36: =SUM(T2:T34) -> 18832.227
A37: t(q) | B37: =LN(B36)/LN(SUM(накопительные!B2:B34)) -> 2.6705494 | C37: =LN(C36)/LN(SUM(накопительные!C2:C34)) -> 2.001156 | D37: =LN(D36)/LN(SUM(накопительные!D2:D34)) -> 1.8504818 | E37: =LN(E36)/LN(SUM(накопительные!E2:E34)) -> 1.7450033 | F37: =LN(F36)/LN(SUM(накопительные!F2:F34)) -> 2.0777463 | G37: =LN(G36)/LN(SUM(накопительные!G2:G34)) -> 2.0055746 | H37: =LN(H36)/LN(SUM(накопительные!H2:H34)) -> 1.9463992 | I37: =LN(I36)/LN(SUM(накопительные!I2:I34)) -> 1.7625171 | ... T37: =LN(T36)/LN(SUM(накопительные!T2:T34)) -> 1.51632
A39: q | B39: -1

Sheet q = -2
A1: № | B1: 1 | C1: 2 | D1: 3 | E1: 4 | F1: 5 | G1: 6 | H1: 7 | I1: 8 | J1: 9 | K1: 10 | L1: 11 | M1: 12 | N1: 13 | O1: 14 | P1: 15 | Q1: 16 | R1: 17 | S1: 18 | T1: 19
A2: Брусника | B2: =IF(накопительные!B2 = 0, 0,(накопительные!B2/SUM(накопительные!B$2:B$34))^$B$39) -> 16.292231 | C2: =IF(накопительные!C2 = 0, 0,(накопительные!C2/SUM(накопительные!C$2:C$34))^$B$39) -> 195.78045 | D2: =IF(накопительные!D2 = 0, 0,(накопительные!D2/SUM(накопительные!D$2:D$34))^$B$39) -> 193.79892 | E2: =IF(накопительные!E2 = 0, 0,(накопительные!E2/SUM(накопительные!E$2:E$34))^$B$39) -> 346.77508 | F2: =IF(накопительные!F2 = 0, 0,(накопительные!F2/SUM(накопительные!F$2:F$34))^$B$39) -> 547.90166 | G2: =IF(накопительные!G2 = 0, 0,(накопительные!G2/SUM(накопительные!G$2:G$34))^$B$39) -> 773.32708 | H2: =IF(накопительные!H2 = 0, 0,(накопительные!H2/SUM(накопительные!H$2:H$34))^$B$39) -> 997.82203 | I2: =IF(накопительные!I2 = 0, 0,(накопительные!I2/SUM(накопительные!I$2:I$34))^$B$39) -> 1176.4399 | ... T2: =IF(накопительные!T2 = 0, 0,(накопительные!T2/SUM(накопительные!T$2:T$34))^$B$39) -> 6713.2068
A3: Вейник | B3: =IF(накопительные!B3 = 0, 0,(накопительные!B3/SUM(накопительные!B$2:B$34))^$B$39) -> 5.607424 | C3: =IF(накопительные!C3 = 0, 0,(накопительные!C3/SUM(накопительные!C$2:C$34))^$B$39) -> 2.5146912 | D3: =IF(накопительные!D3 = 0, 0,(накопительные!D3/SUM(накопительные!D$2:D$34))^$B$39) -> 3.6084862 | E3: =IF(накопительные!E3 = 0, 0,(накопительные!E3/SUM(накопительные!E$2:E$34))^$B$39) -> 3.3686773 | F3: =IF(накопительные!F3 = 0, 0,(накопительные!F3/SUM(накопительные!F$2:F$34))^$B$39) -> 4.4863381 | G3: =IF(накопительные!G3 = 0, 0,(накопительные!G3/SUM(накопительные!G$2:G$34))^$B$39) -> 5.4629742 | H3: =IF(накопительные!H3 = 0, 0,(накопительные!H3/SUM(накопительные!H$2:H$34))^$B$39) -> 4.7102495 | I3: =IF(накопительные!I3 = 0, 0,(накопительные!I3/SUM(накопительные!I$2:I$34))^$B$39) -> 5.0938886 | ... T3: =IF(накопительные!T3 = 0, 0,(накопительные!T3/SUM(накопительные!T$2:T$34))^$B$39) -> 7.9653408
A4: Вероника дубравная | B4: =IF(накопительные!B4 = 0, 0,(накопительные!B4/SUM(накопительные!B$2:B$34))^$B$39) -> 0 | C4: =IF(накопительные!C4 = 0, 0,(накопительные!C4/SUM(накопительные!C$2:C$34))^$B$39) -> 0 | D4: =IF(накопительные!D4 = 0, 0,(накопительные!D4/SUM(накопительные!D$2:D$34))^$B$39) -> 0 | E4: =IF(накопительные!E4 = 0, 0,(накопительные!E4/SUM(накопительные!E$2:E$34))^$B$39) -> 0 | F4: =IF(накопительные!F4 = 0, 0,(накопительные!F4/SUM(накопительные!F$2:F$34))^$B$39) -> 0 | G4: =IF(накопительные!G4 = 0, 0,(накопительные!G4/SUM(накопительные!G$2:G$34))^$B$39) -> 14514576 | H4: =IF(накопительные!H4 = 0, 0,(накопительные!H4/SUM(накопительные!H$2:H$34))^$B$39) -> 9555164.2 | I4: =IF(накопительные!I4 = 0, 0,(накопительные!I4/SUM(накопительные!I$2:I$34))^$B$39) -> 8625234.8 | ... T4: =IF(накопительные!T4 = 0, 0,(накопительные!T4/SUM(накопительные!T$2:T$34))^$B$39) -> 5548885
A5: Герань | B5: =IF(накопительные!B5 = 0, 0,(накопительные!B5/SUM(накопительные!B$2:B$34))^$B$39) -> 350464 | C5: =IF(накопительные!C5 = 0, 0,(накопительные!C5/SUM(накопительные!C$2:C$34))^$B$39) -> 96261.807 | D5: =IF(накопительные!D5 = 0, 0,(накопительные!D5/SUM(накопительные!D$2:D$34))^$B$39) -> 171900.37 | E5: =IF(накопительные!E5 = 0, 0,(накопительные!E5/SUM(накопительные!E$2:E$34))^$B$39) -> 149417.39 | F5: =IF(накопительные!F5 = 0, 0,(накопительные!F5/SUM(накопительные!F$2:F$34))^$B$39) -> 6901.9076 | G5: =IF(накопительные!G5 = 0, 0,(накопительные!G5/SUM(накопительные!G$2:G$34))^$B$39) -> 5246.0553 | H5: =IF(накопительные!H5 = 0, 0,(накопительные!H5/SUM(накопительные!H$2:H$34))^$B$39) -> 6282.1592 | I5: =IF(накопительные!I5 = 0, 0,(накопительные!I5/SUM(накопительные!I$2:I$34))^$B$39) -> 7246.5741 | ... T5: =IF(накопительные!T5 = 0, 0,(накопительные!T5/SUM(накопительные!T$2:T$34))^$B$39) -> 13203.772
A6: Горошик лесной | B6: =IF(накопительные!B6 = 0, 0,(накопительные!B6/SUM(накопительные!B$2:B$34))^$B$39) -> 0 | C6: =IF(накопительные!C6 = 0, 0,(накопительные!C6/SUM(накопительные!C$2:C$34))^$B$39) -> 0 | D6: =IF(накопительные!D6 = 0, 0,(накопительные!D6/SUM(накопительные!D$2:D$34))^$B$39) -> 0 | E6: =IF(накопительные!E6 = 0, 0,(накопительные!E6/SUM(накопительные!E$2:E$34))^$B$39) -> 0 | F6: =IF(накопительные!F6 = 0, 0,(накопительные!F6/SUM(накопительные!F$2:F$34))^$B$39) -> 2.5708916e+08 | G6: =IF(накопительные!G6 = 0, 0,(накопительные!G6/SUM(накопительные!G$2:G$34))^$B$39) -> 3.628644e+08 | H6: =IF(накопительные!H6 = 0, 0,(накопительные!H6/SUM(накопительные!H$2:H$34))^$B$39) -> 4.6820304e+08 | I6: =IF(накопительные!I6 = 0, 0,(накопительные!I6/SUM(накопительные!I$2:I$34))^$B$39) -> 15333751 | ... T6: =IF(накопительные!T6 = 0, 0,(накопительные!T6/SUM(накопительные!T$2:T$34))^$B$39) -> 235203.6
A7: Грушанка | B7: =IF(накопительные!B7 = 0, 0,(накопительные!B7/SUM(накопительные!B$2:B$34))^$B$39) -> 0 | C7: =IF(накопительные!C7 = 0, 0,(накопительные!C7/SUM(накопительные!C$2:C$34))^$B$39) -> 0 | D7: =IF(накопительные!D7 = 0, 0,(накопительные!D7/SUM(накопительные!D$2:D$34))^$B$39) -> 909352.96 | E7: =IF(накопительные!E7 = 0, 0,(накопительные!E7/SUM(накопительные!E$2:E$34))^$B$39) -> 1627155.4 | F7: =IF(накопительные!F7 = 0, 0,(накопительные!F7/SUM(накопительные!F$2:F$34))^$B$39) -> 2570891.6 | G7: =IF(накопительные!G7 = 0, 0,(накопительные!G7/SUM(накопительные!G$2:G$34))^$B$39) -> 3628644 | H7: =IF(накопительные!H7 = 0, 0,(накопительные!H7/SUM(накопительные!H$2:H$34))^$B$39) -> 3251410 | I7: =IF(накопительные!I7 = 0, 0,(накопительные!I7/SUM(накопительные!I$2:I$34))^$B$39) -> 3833437.7 | ... T7: =IF(накопительные!T7 = 0, 0,(накопительные!T7/SUM(накопительные!T$2:T$34))^$B$39) -> 11244.523
A8: Звездчатка жестколистная | B8: =IF(накопительные!B8 = 0, 0,(накопительные!B8/SUM(накопительные!B$2:B$34))^$B$39) -> 0 | C8: =IF(накопительные!C8 = 0, 0,(накопительные!C8/SUM(накопительные!C$2:C$34))^$B$39) -> 0 | D8: =IF(накопительные!D8 = 0, 0,(накопительные!D8/SUM(накопительные!D$2:D$34))^$B$39) -> 0 | E8: =IF(накопительные!E8 = 0, 0,(накопительные!E8/SUM(накопительные!E$2:E$34))^$B$39) -> 0 | F8: =IF(накопительные!F8 = 0, 0,(накопительные!F8/SUM(накопительные!F$2:F$34))^$B$39) -> 0 | G8: =IF(накопительные!G8 = 0, 0,(накопительные!G8/SUM(накопительные!G$2:G$34))^$B$39) -> 145145.76 | H8: =IF(накопительные!H8 = 0, 0,(накопительные!H8/SUM(накопительные!H$2:H$34))^$B$39) -> 64803.189 | I8: =IF(накопительные!I8 = 0, 0,(накопительные!I8/SUM(накопительные!I$2:I$34))^$B$39) -> 61165.1 | ... T8: =IF(накопительные!T8 = 0, 0,(накопительные!T8/SUM(накопительные!T$2:T$34))^$B$39) -> 7150.437
A9: Земляника | B9: =IF(накопительные!B9 = 0, 0,(накопительные!B9/SUM(накопительные!B$2:B$34))^$B$39) -> 0 | C9: =IF(накопительные!C9 = 0, 0,(накопительные!C9/SUM(накопительные!C$2:C$34))^$B$39) -> 0 | D9: =IF(накопительные!D9 = 0, 0,(накопительные!D9/SUM(накопительные!D$2:D$34))^$B$39) -> 0 | E9: =IF(накопительные!E9 = 0, 0,(накопительные!E9/SUM(накопительные!E$2:E$34))^$B$39) -> 0 | F9: =IF(накопительные!F9 = 0, 0,(накопительные!F9/SUM(накопительные!F$2:F$34))^$B$39) -> 0 | G9: =IF(накопительные!G9 = 0, 0,(накопительные!G9/SUM(накопительные!G$2:G$34))^$B$39) -> 0 | H9: =IF(накопительные!H9 = 0, 0,(накопительные!H9/SUM(накопительные!H$2:H$34))^$B$39) -> 0 | I9: =IF(накопительные!I9 = 0, 0,(накопительные!I9/SUM(накопительные!I$2:I$34))^$B$39) -> 0 | ... T9: =IF(накопительные!T9 = 0, 0,(накопительные!T9/SUM(накопительные!T$2:T$34))^$B$39) -> 22470.691
